Workbook

Sheet Contents
A1: The New Zealand 2023 Vehicle Fleet : Data Spreadsheet | D1: Analysis produced by Ministry of Transport
A2: October/November 2024 | D2: info@transport.govt.nz
A4: Overview | C4: Vehicles entering and leaving the fleet
A5: Tab 1.1 Composition of the NZ Fleet | C5: Entering and leaving
A6: Tab 1.2 Composition of the NZ fleet relative to Jan 2000 | C6: Tab 5.1 Entry and exit from the fleet
A7: Tab 1.1 extra Fleet Average Age | C7: Tab 5.2abcd Vehicles entering/leaving the fleet by Year of Manufacture
A8: Tab 1.3 Total collective distance travelled
A9: Tab 1.4 Light fleet travel by year | C9: Entering
A10: Tab 1.4b Regional vehicle travel | C10: Tab 6.1 Number of New/used imports entering the light fleet by year
A11: Tab 1.5 Light fleet ownership per capita by year | C11: Tab 6.2b Used light imports : Year of manufacture and fuel
A12: Tab 1.5b Regional light fleet ownership per capita | C12: Tab 6.2c Average age of used imports entering the truck and bus fleets by year
A13: Tab 1.6 Light fleet travel per capita by year | C13: Tab 6.3 Average engine size of vehicles entering the light fleet, by petrol/diesel and year
A14: Tab 1.7 Light fleet average vehicle travel by year | C14: Tab 6.4a Numbers of used imports entering the light fleet, by engize size band and year
C15: Tab 6.4b Numbers of New entering the light fleet, by engize size band and year
A16: Composition of the Fleet | C16: Tab 6.5a Numbers of motorcycles entering the fleet, by engize size band and year
A17: Tab 2.1 Number of new/used light vehicles by year | C17: Tab 6.5b Average engine capacity of motorcycles entering the fleet, by year
A18: Tab 2.2 Percentage of used imports in the light/truck/bus fleets, by year | C18: Tab 6.7a Vehicles entering the fleet: country of manufacture
A19: Tab 2.3 Average age of Light, Trucks and Buses by year | C19: Tab 6.7b Vehicles entering the fleet: country imported from
A20: Tab 2.4 Light fleet average age in detail, by year
A21: Tab 2.5a Light fleet year of manufacture | C21: Leaving
A22: Tab 2.6a Motorcycle year of manufacture | C22: Tab 7.1a Number of light fleet used imports/New scrapped, by year
A23: Tab 2.7a Truck year of manufacture | C23: Tab 7.1b Number of heavy fleet used imports/New scrapped, by year
A24: Tab 2.8a Bus year of manufacture | C24: Tab 7.2a Average age of light fleet used imports/New when scrapped, by year
A25: Tab 2.9 Heavy vehicle mass | C25: Tab 7.2b Average age of heavy fleet used imports/New when scrapped, by year
A26: Tab 2.10 Light fleet age distribution | C26: Tab 7.3a,b,c Last odometer reading of scrapped vehicles
C27: Tab 7.3d,e Last odometer reading of scrapped vehicles
A28: Vehicle age and travel
A29: Tab 3.1 Total LPV, LCV, Truck and Bus travel by year of manufacture in 5 year blocks | C29: Petrol/Diesel vehicles and travel, CNG/LPG/electric/Hybrid
A30: Tab 3.2 Light, truck, bus travel by new/used, by year of manufacture in 5 year blocks | C30: Tab 8.1 Diesel vehicles in the light, truck and bus fleets
A31: Tab 3.4 LPV, LCV, Truck and Bus travel per vehicle by year of manufacture in 5 year blocks | C31: Tab 8.2 Petrol and diesel travel
A32: Tab 3.5 Average light travel by year of manufacture | C32: Tab 8.2a Percentage of light passenger/commercial vehicles by petrol/diesel
A33: Tab 3.6 Light fleet travel by engine size | C33: Tab 8.2b Percentage of light passenger/commercial travel by petrol/diesel
C34: Tab 8.3 Light fleet petrol and diesel travel by year of manufacture in 5 year blocks
A35: Engine capacity trends | C35: Tab 8.4 Light vehicle fleet by fuel type
A36: Tab 4.1 Light fleet average engine capacity by petrol/diesel by year | C36: Tab 8.5 Primary fuel types by vehicle type
A37: Tab 4.2 Number of light vehicles by engine capacity by year
A38: Tab 4.3a Light passenger average travel by cc band, by year of manufacture
A39: Tab 4.3b Light commercial average travel by cc band, by year of manufacture | C39: Emissions of vehicles entering the light fleet
A40: Tab 4.4 Motorcycle fleet engine composition by year | C40: Tab 9.1 Average quarterly CO2 emissions of light fleet registrations
C41: Tab 9.2 Emissions standards of vehicles in the light fleet
...

Sheet 1.1, 1.2
B1: Fleet Composition | K1: Change Relative to 2000 | T1: Back to Contents
A2: Period | B2: Light passenger | C2: Light commercial | D2: MCycle | E2: Trucks | F2: Bus | G2: Other | H2: Total | I2: Total light | K2: =B2 -> Light passenger | L2: =C2 -> Light commercial | M2: =D2 -> MCycle | N2: =E2 -> Trucks | O2: =F2 -> Bus | P2: =G2 -> Other | Q2: =H2 -> Total | R2: =I2 -> Total light
A3: 2000 | B3: 2147516 | C3: 347339 | D3: 78641 | E3: 95622 | F3: 4412 | G3: 12288 | H3: =SUM(B3:G3) -> 2685818 | I3: =B3+C3 -> 2494855 | K3: - | L3: - | M3: - | N3: - | O3: - | P3: - | Q3: - | R3: -
A4: 2001 | B4: 2213672 | C4: 349979 | D4: 79230 | E4: 97867 | F4: 4698 | G4: 12488 | H4: =SUM(B4:G4) -> 2757934 | I4: =B4+C4 -> 2563651 | K4: =B4/B$3-1 -> 0.030805824 | L4: =C4/C$3-1 -> 0.0076006438 | M4: =D4/D$3-1 -> 0.0074897318 | N4: =E4/E$3-1 -> 0.023477861 | O4: =F4/F$3-1 -> 0.064823209 | P4: =G4/G$3-1 -> 0.016276042 | Q4: =H4/H$3-1 -> 0.026850665 | R4: =H4/H$3-1 -> 0.026850665
A5: 2002 | B5: 2292383 | C5: 355629 | D5: 80760 | E5: 101701 | F5: 5084 | G5: 13103 | H5: =SUM(B5:G5) -> 2848660 | I5: =B5+C5 -> 2648012 | K5: =B5/B$3-1 -> 0.067457937 | L5: =C5/C$3-1 -> 0.023867173 | M5: =D5/D$3-1 -> 0.026945232 | N5: =E5/E$3-1 -> 0.063573236 | O5: =F5/F$3-1 -> 0.15231188 | P5: =G5/G$3-1 -> 0.06632487 | Q5: =H5/H$3-1 -> 0.060630318 | R5: =H5/H$3-1 -> 0.060630318
A6: 2003 | B6: 2395130 | C6: 364350 | D6: 83623 | E6: 106870 | F6: 5451 | G6: 13747 | H6: =SUM(B6:G6) -> 2969171 | I6: =B6+C6 -> 2759480 | K6: =B6/B$3-1 -> 0.11530252 | L6: =C6/C$3-1 -> 0.048975209 | M6: =D6/D$3-1 -> 0.063351178 | N6: =E6/E$3-1 -> 0.11762983 | O6: =F6/F$3-1 -> 0.23549411 | P6: =G6/G$3-1 -> 0.11873372 | Q6: =H6/H$3-1 -> 0.1054997 | R6: =H6/H$3-1 -> 0.1054997
A7: 2004 | B7: 2490911 | C7: 376168 | D7: 88466 | E7: 113751 | F7: 5876 | G7: 14400 | H7: =SUM(B7:G7) -> 3089572 | I7: =B7+C7 -> 2867079 | K7: =B7/B$3-1 -> 0.15990335 | L7: =C7/C$3-1 -> 0.082999606 | M7: =D7/D$3-1 -> 0.12493483 | N7: =E7/E$3-1 -> 0.18959026 | O7: =F7/F$3-1 -> 0.3318223 | P7: =G7/G$3-1 -> 0.171875 | Q7: =H7/H$3-1 -> 0.15032813 | R7: =H7/H$3-1 -> 0.15032813
A8: 2005 | B8: 2578516 | C8: 388686 | D8: 97398 | E8: 119819 | F8: 6205 | G8: 15015 | H8: =SUM(B8:G8) -> 3205639 | I8: =B8+C8 -> 2967202 | K8: =B8/B$3-1 -> 0.20069699 | L8: =C8/C$3-1 -> 0.11903932 | M8: =D8/D$3-1 -> 0.23851426 | N8: =E8/E$3-1 -> 0.25304846 | O8: =F8/F$3-1 -> 0.40639166 | P8: =G8/G$3-1 -> 0.22192383 | Q8: =H8/H$3-1 -> 0.1935429 | R8: =H8/H$3-1 -> 0.1935429
A9: 2006 | B9: 2631661 | C9: 398206 | D9: 108056 | E9: 124349 | F9: 6449 | G9: 15319 | H9: =SUM(B9:G9) -> 3284040 | I9: =B9+C9 -> 3029867 | K9: =B9/B$3-1 -> 0.22544419 | L9: =C9/C$3-1 -> 0.14644771 | M9: =D9/D$3-1 -> 0.37404153 | N9: =E9/E$3-1 -> 0.3004225 | O9: =F9/F$3-1 -> 0.46169538 | P9: =G9/G$3-1 -> 0.24666341 | Q9: =H9/H$3-1 -> 0.22273363 | R9: =H9/H$3-1 -> 0.22273363
A10: 2007 | B10: 2679348 | C10: 409538 | D10: 119784 | E10: 128816 | F10: 6881 | G10: 15546 | H10: =SUM(B10:G10) -> 3359913 | I10: =B10+C10 -> 3088886 | K10: =B10/B$3-1 -> 0.24764984 | L10: =C10/C$3-1 -> 0.17907289 | M10: =D10/D$3-1 -> 0.52317493 | N10: =E10/E$3-1 -> 0.34713769 | O10: =F10/F$3-1 -> 0.55961015 | P10: =G10/G$3-1 -> 0.26513672 | Q10: =H10/H$3-1 -> 0.25098313 | R10: =H10/H$3-1 -> 0.25098313
A11: 2008 | B11: 2692948 | C11: 416004 | D11: 133685 | E11: 131259 | F11: 7329 | G11: 15865 | H11: =SUM(B11:G11) -> 3397090 | I11: =B11+C11 -> 3108952 | K11: =B11/B$3-1 -> 0.25398274 | L11: =C11/C$3-1 -> 0.19768871 | M11: =D11/D$3-1 -> 0.69994023 | N11: =E11/E$3-1 -> 0.3726862 | O11: =F11/F$3-1 -> 0.66115141 | P11: =G11/G$3-1 -> 0.29109701 | Q11: =H11/H$3-1 -> 0.26482509 | R11: =H11/H$3-1 -> 0.26482509
A12: 2009 | B12: 2684863 | C12: 415398 | D12: 138534 | E12: 130405 | F12: 7697 | G12: 15812 | H12: =SUM(B12:G12) -> 3392709 | I12: =B12+C12 -> 3100261 | K12: =B12/B$3-1 -> 0.25021793 | L12: =C12/C$3-1 -> 0.19594402 | M12: =D12/D$3-1 -> 0.76160018 | N12: =E12/E$3-1 -> 0.3637552 | O12: =F12/F$3-1 -> 0.74456029 | P12: =G12/G$3-1 -> 0.28678385 | Q12: =H12/H$3-1 -> 0.26319393 | R12: =H12/H$3-1 -> 0.26319393
A13: 2010 | B13: 2705457 | C13: 417462 | D13: 140372 | E13: 129044 | F13: 7832 | G13: 15547 | H13: =SUM(B13:G13) -> 3415714 | I13: =B13+C13 -> 3122919 | K13: =B13/B$3-1 -> 0.25980761 | L13: =C13/C$3-1 -> 0.20188634 | M13: =D13/D$3-1 -> 0.78497222 | N13: =E13/E$3-1 -> 0.34952208 | O13: =F13/F$3-1 -> 0.77515866 | P13: =G13/G$3-1 -> 0.2652181 | Q13: =H13/H$3-1 -> 0.27175929 | R13: =H13/H$3-1 -> 0.27175929
A14: 2011 | B14: 2698491 | C14: 419672 | D14: 140984 | E14: 127823 | F14: 7939 | G14: 15776 | H14: =SUM(B14:G14) -> 3410685 | I14: =B14+C14 -> 3118163 | K14: =B14/B$3-1 -> 0.25656386 | L14: =C14/C$3-1 -> 0.208249 | M14: =D14/D$3-1 -> 0.79275442 | N14: =E14/E$3-1 -> 0.33675305 | O14: =F14/F$3-1 -> 0.7994107 | P14: =G14/G$3-1 -> 0.28385417 | Q14: =H14/H$3-1 -> 0.26988687 | R14: =H14/H$3-1 -> 0.26988687
A15: 2012 | B15: 2736658 | C15: 429688 | D15: 143732 | E15: 127837 | F15: 8063 | G15: 16107 | H15: =SUM(B15:G15) -> 3462085 | I15: =B15+C15 -> 3166346 | K15: =B15/B$3-1 -> 0.27433649 | L15: =C15/C$3-1 -> 0.23708538 | M15: =D15/D$3-1 -> 0.82769802 | N15: =E15/E$3-1 -> 0.33689946 | O15: =F15/F$3-1 -> 0.82751587 | P15: =G15/G$3-1 -> 0.31079102 | Q15: =H15/H$3-1 -> 0.28902442 | R15: =H15/H$3-1 -> 0.28902442
... A26: 2023 | B26: 3509955 | C26: 755025 | D26: 203183 | E26: 170868 | F26: 11519 | G26: 39122 | H26: =SUM(B26:G26) -> 4689672 | I26: =B26+C26 -> 4264980 | K26: =B26/B$3-1 -> 0.63442554 | L26: =C26/C$3-1 -> 1.1737409 | M26: =D26/D$3-1 -> 1.5836777 | N26: =E26/E$3-1 -> 0.78691096 | O26: =F26/F$3-1 -> 1.6108341 | P26: =G26/G$3-1 -> 2.1837565 | Q26: =H26/H$3-1 -> 0.74608704 | R26: =H26/H$3-1 -> 0.74608704

Sheet 1.1extra
B1: Fleet Average Age | M1: Fleet Average Age (By Fuel) | R1: Number of vehicles | W1: Back to Contents
A2: Period | B2: Light Passenger | C2: Light Commercial | D2: Light New | E2: Light Used Imports | F2: Total Light Vehicles | G2: MCycle | H2: Heavy Commercial | I2: Bus | J2: Other | K2: Overall | M2: Light new petrol | N2: light used petrol | O2: Light new diesel | P2: Light used diesel | R2: New petrol | S2: Used petrol | T2: New diesel | U2: Used diesel
A3: 2000 | B3: 11.725915 | C3: 12.436974 | D3: 12.005417 | E3: 11.546687 | F3: 11.82491 | G3: 16.194421 | H3: 14.321275 | I3: 16.177697 | J3: 17.345785 | K3: 11.954116 | M3: 12.4 | N3: 11.7 | O3: 7 | P3: 10.8 | R3: 1408018 | S3: 793410 | T3: 105129 | U3: 188298
A4: 2001 | B4: 11.876418 | C4: 12.622339 | D4: 12.076298 | E4: 11.840708 | F4: 11.978248 | G4: 16.593658 | H4: 14.61203 | I4: 16.300128 | J4: 17.294443 | K4: 12.111692 | M4: 12.5 | N4: 11.9 | O4: 7 | P4: 11.5 | R4: 1380351 | S4: 869784 | T4: 116337 | U4: 197179
A5: 2002 | B5: 11.970411 | C5: 12.705373 | D5: 12.079227 | E5: 12.056082 | F5: 12.069117 | G5: 16.818567 | H5: 14.727603 | I5: 16.313533 | J5: 16.963329 | K5: 12.203679 | M5: 12.6 | N5: 12.1 | O5: 7 | P5: 12 | R5: 1363113 | S5: 946207 | T5: 128201 | U5: 210491
A6: 2003 | B6: 12.02384 | C6: 12.716392 | D6: 12.025735 | E6: 12.221579 | F6: 12.115282 | G6: 16.819015 | H6: 14.768279 | I6: 16.243166 | J6: 16.598058 | K6: 12.248121 | M6: 12.5 | N6: 12.2 | O6: 7.1 | P6: 12.3 | R6: 1357037 | S6: 1031579 | T6: 140711 | U6: 230153
A7: 2004 | B7: 12.106601 | C7: 12.667115 | D7: 11.927096 | E7: 12.462061 | F7: 12.180142 | G7: 16.468655 | H7: 14.751013 | I7: 16.095984 | J7: 16.287014 | K7: 12.306719 | M7: 12.5 | N7: 12.4 | O7: 7.1 | P7: 12.7 | R7: 1355829 | S7: 1109629 | T7: 155084 | U7: 246537
A8: 2005 | B8: 12.225264 | C8: 12.598181 | D8: 11.81606 | E8: 12.761644 | F8: 12.274114 | G8: 15.682442 | H8: 14.753791 | I8: 16.178888 | J8: 15.884549 | K8: 12.388731 | M8: 12.4 | N8: 12.7 | O8: 7.1 | P8: 13.2 | R8: 1357015 | S8: 1178584 | T8: 172835 | U8: 258768
A9: 2006 | B9: 12.41462 | C9: 12.612246 | D9: 11.750668 | E9: 13.16255 | F9: 12.440594 | G9: 15.011101 | H9: 14.941841 | I9: 16.549 | J9: 15.909622 | K9: 12.546459 | M9: 12.4 | N9: 13 | O9: 7.1 | P9: 13.8 | R9: 1357891 | S9: 1220622 | T9: 191411 | U9: 259943
A10: 2007 | B10: 12.604469 | C10: 12.585953 | D10: 11.692788 | E10: 13.545775 | F10: 12.602014 | G10: 14.357093 | H10: 15.115203 | I10: 16.596062 | J10: 15.949698 | K10: 12.697148 | M10: 12.4 | N10: 13.4 | O10: 7.1 | P10: 14.4 | R10: 1359785 | S10: 1258427 | T10: 213442 | U10: 257232
A11: 2008 | B11: 12.856607 | C11: 12.650997 | D11: 11.70133 | E11: 14.015423 | F11: 12.829095 | G11: 13.74836 | H11: 15.328705 | I11: 16.498363 | J11: 15.83451 | K11: 12.909875 | M11: 12.5 | N11: 13.8 | O11: 7.1 | P11: 15.1 | R11: 1358019 | S11: 1269191 | T11: 235796 | U11: 245946
A12: 2009 | B12: 13.246121 | C12: 12.980888 | D12: 11.948539 | E12: 14.555685 | F12: 13.210583 | G12: 14.028166 | H12: 15.811944 | I12: 16.299402 | J12: 15.970339 | K12: 13.290655 | M12: 12.8 | N12: 14.3 | O12: 7.4 | P12: 15.8 | R12: 1347813 | S12: 1267587 | T12: 251701 | U12: 233160
A13: 2010 | B13: 13.545504 | C13: 13.198103 | D13: 12.114408 | E13: 14.986964 | F13: 13.499064 | G13: 14.471711 | H13: 16.277948 | I13: 16.51213 | J13: 16.321831 | K13: 13.585109 | M13: 13 | N13: 14.7 | O13: 7.6 | P13: 16.6 | R13: 1346895 | S13: 1285930 | T13: 270686 | U13: 219408
A14: 2011 | B14: 13.826252 | C14: 13.328117 | D14: 12.236375 | E14: 15.433096 | F14: 13.759208 | G14: 14.992474 | H14: 16.665573 | I14: 16.536906 | J14: 16.474772 | K14: 13.85268 | M14: 13.2 | N14: 15.1 | O14: 7.7 | P14: 17.4 | R14: 1341315 | S14: 1282191 | T14: 291438 | U14: 203219
... A26: 2023 | B26: 14.982094 | C26: 12.777961 | D26: 12.088563 | E26: 18.079849 | F26: 14.591899 | G26: 18.629553 | H26: 17.827984 | I26: 16.80428 | J26: 15.987935 | K26: 14.754208 | M26: 13.4 | N26: 17.7 | O26: 9.2 | P26: 21.9 | R26: 1720821 | S26: 1637646 | T26: 762125 | U26: 144388

Sheet 1.3
B1: Total collective distance travelled | J1: Back to Contents
B2: Light passenger New | C2: Light passenger used import | D2: Light commercial New | E2: Light commercial used import | F2: Truck | G2: Other | H2: Total
A3: Distance (million km) | B3: 18914.672 | C3: 16068.593 | D3: 9285.5258 | E3: 1216.4355 | F3: 3236.842 | G3: 697.25676 | H3: =SUM(B3:G3) -> 49419.326
A4: Proportion | B4: =B3/$H3 -> 0.38273837 | C4: =C3/$H3 -> 0.32514797 | D4: =D3/$H3 -> 0.1878926 | E4: =E3/$H3 -> 0.024614571 | F4: =F3/$H3 -> 0.065497494 | G4: =G3/$H3 -> 0.01410899 | H4: -

Sheet 1.4 to 1.7
B1: Travel and ownership trends | N1: Travel breakdown by vehicle type | U1: Back to Contents
A2: Period | B2: Light vehicles live at Dec 31st (*) | C2: Light travel | D2: Other travel | E2: Popn (**) | F2: Light vehicles per 1000 | G2: Light passenger vehicles per 1000 | H2: Light commercial vehicles per 1000 | I2: Light travel per capita | J2: Light travel per vehicle | K2: Population growth | L2: Light fleet growth | N2: Light passenger travel | O2: Light commercial travel | P2: Heavy truck travel | Q2: Heavy bus travel | R2: Motorcycle / moped travel | S2: Other | T2: Total (billion) | U2: Travel per capita (km/head) | V2: Light passenger travel per capita | W2: Light commercial travel per capita
A3: 2000 | B3: ='1.1, 1.2'!I3 -> 2494855 | E3: 3857.7 | F3: =B3/E3 -> 646.72084 | G3: ='1.1, 1.2'!B3/E3 -> 556.683 | H3: ='1.1, 1.2'!C3/E3 -> 90.037846
A4: 2001 | B4: ='1.1, 1.2'!I4 -> 2563651 | C4: 33.979814 | D4: 2.5904145 | E4: 3880.5 | F4: =B4/E4 -> 660.64966 | G4: ='1.1, 1.2'!B4/E4 -> 570.46051 | H4: ='1.1, 1.2'!C4/E4 -> 90.189151 | I4: =C4*1000000/E4 -> 8756.5557 | J4: =C4/B4*1000000000 -> 13254.462 | N4: 28.798268 | O4: 5.1815464 | P4: 2.1892506 | Q4: 0.14085492 | R4: 0.2315034 | S4: 0.028805609 | T4: =SUM(N4:S4) -> 36.570229 | U4: =T4/E4*1000000 -> 9424.1023 | V4: =N4/E4*1000000 -> 7421.2776 | W4: =O4/E4*1000000 -> 1335.278
A5: 2002 | B5: ='1.1, 1.2'!I5 -> 2648012 | C5: 35.073463 | D5: 2.697897 | E5: 3948.5 | F5: =B5/E5 -> 670.63746 | G5: ='1.1, 1.2'!B5/E5 -> 580.5706 | H5: ='1.1, 1.2'!C5/E5 -> 90.066861 | I5: =C5*1000000/E5 -> 8882.7309 | J5: =C5/B5*1000000000 -> 13245.206 | K5: =E5/E4-1 -> 0.017523515 | L5: =B5/B4-1 -> 0.032906585 | N5: 29.794649 | O5: 5.2788141 | P5: 2.2825877 | Q5: 0.14989798 | R5: 0.22940041 | S5: 0.036010957 | T5: =SUM(N5:S5) -> 37.77136 | U5: =T5/E5*1000000 -> 9566.0023 | V5: =N5/E5*1000000 -> 7545.8146 | W5: =O5/E5*1000000 -> 1336.9163
A6: 2003 | B6: ='1.1, 1.2'!I6 -> 2759480 | C6: 36.140777 | D6: 2.7992663 | E6: 4027.2 | F6: =B6/E6 -> 685.21057 | G6: ='1.1, 1.2'!B6/E6 -> 594.73828 | H6: ='1.1, 1.2'!C6/E6 -> 90.472288 | I6: =C6*1000000/E6 -> 8974.1699 | J6: =C6/B6*1000000000 -> 13096.952 | K6: =E6/E5-1 -> 0.01993162 | L6: =B6/B5-1 -> 0.042094975 | N6: 30.74631 | O6: 5.3944671 | P6: 2.3631249 | Q6: 0.15966194 | R6: 0.23192044 | S6: 0.044559044 | T6: =SUM(N6:S6) -> 38.940043 | U6: =T6/E6*1000000 -> 9669.2599 | V6: =N6/E6*1000000 -> 7634.6618 | W6: =O6/E6*1000000 -> 1339.5081
A7: 2004 | B7: ='1.1, 1.2'!I7 -> 2867079 | C7: 37.099953 | D7: 2.9810789 | E7: 4087.5 | F7: =B7/E7 -> 701.42606 | G7: ='1.1, 1.2'!B7/E7 -> 609.39719 | H7: ='1.1, 1.2'!C7/E7 -> 92.028869 | I7: =C7*1000000/E7 -> 9076.4412 | J7: =C7/B7*1000000000 -> 12939.983 | K7: =E7/E6-1 -> 0.014973182 | L7: =B7/B6-1 -> 0.038992491 | N7: 31.540927 | O7: 5.5590266 | P7: 2.5131457 | Q7: 0.17675107 | R7: 0.2377725 | S7: 0.053409689 | T7: =SUM(N7:S7) -> 40.081032 | U7: =T7/E7*1000000 -> 9805.7571 | V7: =N7/E7*1000000 -> 7716.4346 | W7: =O7/E7*1000000 -> 1360.0065
A8: 2005 | B8: ='1.1, 1.2'!I8 -> 2967202 | C8: 37.383994 | D8: 3.1114199 | E8: 4133.9 | F8: =B8/E8 -> 717.77305 | G8: ='1.1, 1.2'!B8/E8 -> 623.749 | H8: ='1.1, 1.2'!C8/E8 -> 94.024045 | I8: =C8*1000000/E8 -> 9043.2749 | J8: =C8/B8*1000000000 -> 12599.073 | K8: =E8/E7-1 -> 0.011351682 | L8: =B8/B7-1 -> 0.034921605 | N8: 31.722382 | O8: 5.661612 | P8: 2.5821994 | Q8: 0.1899749 | R8: 0.26674246 | S8: 0.072503173 | T8: =SUM(N8:S8) -> 40.495414 | U8: =T8/E8*1000000 -> 9795.9346 | V8: =N8/E8*1000000 -> 7673.7178 | W8: =O8/E8*1000000 -> 1369.5571
A9: 2006 | B9: ='1.1, 1.2'!I9 -> 3029867 | C9: 37.287193 | D9: 3.2237591 | E9: 4184.6 | F9: =B9/E9 -> 724.05176 | G9: ='1.1, 1.2'!B9/E9 -> 628.89189 | H9: ='1.1, 1.2'!C9/E9 -> 95.159872 | I9: =C9*1000000/E9 -> 8910.5752 | J9: =C9/B9*1000000000 -> 12306.544 | K9: =E9/E8-1 -> 0.012264448 | L9: =B9/B8-1 -> 0.021119223 | N9: 31.531465 | O9: 5.7557282 | P9: 2.6151123 | Q9: 0.19792259 | R9: 0.30311013 | S9: 0.10761409 | T9: =SUM(N9:S9) -> 40.510952 | U9: =T9/E9*1000000 -> 9680.9616 | V9: =N9/E9*1000000 -> 7535.1204 | W9: =O9/E9*1000000 -> 1375.4548
A10: 2007 | B10: ='1.1, 1.2'!I10 -> 3088886 | C10: 37.82497 | D10: 3.2966702 | E10: 4223.8 | F10: =B10/E10 -> 731.30499 | G10: ='1.1, 1.2'!B10/E10 -> 634.34538 | H10: ='1.1, 1.2'!C10/E10 -> 96.95961 | I10: =C10*1000000/E10 -> 8955.1992 | J10: =C10/B10*1000000000 -> 12245.505 | K10: =E10/E9-1 -> 0.0093676815 | L10: =B10/B9-1 -> 0.019479073 | N10: 31.891749 | O10: 5.9332213 | P10: 2.6866017 | Q10: 0.20528989 | R10: 0.33647023 | S10: 0.068308406 | T10: =SUM(N10:S10) -> 41.12164 | U10: =T10/E10*1000000 -> 9735.6978 | V10: =N10/E10*1000000 -> 7550.4874 | W10: =O10/E10*1000000 -> 1404.7117
A11: 2008 | B11: ='1.1, 1.2'!I11 -> 3108952 | C11: 37.220178 | D11: 3.3342536 | E11: 4259.8 | F11: =B11/E11 -> 729.8352 | G11: ='1.1, 1.2'!B11/E11 -> 632.1771 | H11: ='1.1, 1.2'!C11/E11 -> 97.658106 | I11: =C11*1000000/E11 -> 8737.5412 | J11: =C11/B11*1000000000 -> 11971.937 | K11: =E11/E10-1 -> 0.0085231308 | L11: =B11/B10-1 -> 0.0064961931 | N11: 31.197506 | O11: 6.0226721 | P11: 2.6767069 | Q11: 0.21099012 | R11: 0.37588017 | S11: 0.070676351 | T11: =SUM(N11:S11) -> 40.554431 | U11: =T11/E11*1000000 -> 9520.2665 | V11: =N11/E11*1000000 -> 7323.702 | W11: =O11/E11*1000000 -> 1413.8392
A12: 2009 | B12: ='1.1, 1.2'!I12 -> 3100261 | C12: 37.301741 | D12: 3.2158081 | E12: 4302.6 | F12: =B12/E12 -> 720.55525 | G12: ='1.1, 1.2'!B12/E12 -> 624.00944 | H12: ='1.1, 1.2'!C12/E12 -> 96.54581 | I12: =C12*1000000/E12 -> 8669.5814 | J12: =C12/B12*1000000000 -> 12031.807 | K12: =E12/E11-1 -> 0.01004742 | L12: =B12/B11-1 -> -0.0027954758 | N12: 31.28506 | O12: 6.016681 | P12: 2.5361513 | Q12: 0.21732585 | R12: 0.39091731 | S12: 0.071413674 | T12: =SUM(N12:S12) -> 40.517549 | U12: =T12/E12*1000000 -> 9416.9918 | V12: =N12/E12*1000000 -> 7271.1988 | W12: =O12/E12*1000000 -> 1398.3826
A13: 2010 | B13: ='1.1, 1.2'!I13 -> 3122919 | C13: 37.271603 | D13: 3.2138905 | E13: 4350.7 | F13: =B13/E13 -> 717.79691 | G13: ='1.1, 1.2'!B13/E13 -> 621.84407 | H13: ='1.1, 1.2'!C13/E13 -> 95.952835 | I13: =C13*1000000/E13 -> 8566.8061 | J13: =C13/B13*1000000000 -> 11934.861 | K13: =E13/E12-1 -> 0.011179287 | L13: =B13/B12-1 -> 0.0073084169 | N13: 31.218402 | O13: 6.0532019 | P13: 2.5346732 | Q13: 0.22478286 | R13: 0.38595859 | S13: 0.068475833 | T13: =SUM(N13:S13) -> 40.485494 | U13: =T13/E13*1000000 -> 9305.5126 | V13: =N13/E13*1000000 -> 7175.4894 | W13: =O13/E13*1000000 -> 1391.3168
A14: 2011 | B14: ='1.1, 1.2'!I14 -> 3118163 | C14: 36.814735 | D14: 3.2039272 | E14: 4384 | F14: =B14/E14 -> 711.25981 | G14: ='1.1, 1.2'!B14/E14 -> 615.53171 | H14: ='1.1, 1.2'!C14/E14 -> 95.728102 | I14: =C14*1000000/E14 -> 8397.5218 | J14: =C14/B14*1000000000 -> 11806.546 | K14: =E14/E13-1 -> 0.0076539407 | L14: =B14/B13-1 -> -0.0015229342 | N14: 30.737007 | O14: 6.0777282 | P14: 2.5401427 | Q14: 0.22151166 | R14: 0.37483477 | S14: 0.067438085 | T14: =SUM(N14:S14) -> 40.018663 | U14: =T14/E14*1000000 -> 9128.3446 | V14: =N14/E14*1000000 -> 7011.1787 | W14: =O14/E14*1000000 -> 1386.3431
A15: 2012 | B15: ='1.1, 1.2'!I15 -> 3166346 | C15: 36.888903 | D15: 3.1971231 | E15: 4408.1 | F15: =B15/E15 -> 718.30176 | G15: ='1.1, 1.2'!B15/E15 -> 620.82485 | H15: ='1.1, 1.2'!C15/E15 -> 97.476917 | I15: =C15*1000000/E15 -> 8368.436 | J15: =C15/B15*1000000000 -> 11650.307 | K15: =E15/E14-1 -> 0.0054972628 | L15: =B15/B14-1 -> 0.015452367 | N15: 30.705906 | O15: 6.1829965 | P15: 2.5272596 | Q15: 0.22757513 | R15: 0.37346276 | S15: 0.06882562 | T15: =SUM(N15:S15) -> 40.086026 | U15: =T15/E15*1000000 -> 9093.7197 | V15: =N15/E15*1000000 -> 6965.7917 | W15: =O15/E15*1000000 -> 1402.6443
A16: 2013 | B16: ='1.1, 1.2'!I16 -> 3244068 | C16: 37.436152 | D16: 3.2684472 | E16: 4442.1 | F16: =B16/E16 -> 730.30053 | G16: ='1.1, 1.2'!B16/E16 -> 629.17044 | H16: ='1.1, 1.2'!C16/E16 -> 101.1301 | I16: =C16*1000000/E16 -> 8427.5799 | J16: =C16/B16*1000000000 -> 11539.879 | K16: =E16/E15-1 -> 0.0077130737 | L16: =B16/B15-1 -> 0.024546275 | N16: 30.992188 | O16: 6.4439641 | P16: 2.5819011 | Q16: 0.23420849 | R16: 0.38147638 | S16: 0.070861254 | T16: =SUM(N16:S16) -> 40.7046 | U16: =T16/E16*1000000 -> 9163.3686 | V16: =N16/E16*1000000 -> 6976.9227 | W16: =O16/E16*1000000 -> 1450.6571
... A26: 2023 | B26: ='1.1, 1.2'!I26 -> 4264980 | C26: 45.485227 | D26: 4.0241551 | E26: 5245 | F26: =B26/E26 -> 813.15157 | G26: ='1.1, 1.2'!B26/E26 -> 669.20019 | H26: ='1.1, 1.2'!C26/E26 -> 143.95138 | I26: =C26*1000000/E26 -> 8672.1119 | J26: =C26/B26*1000000000 -> 10664.816 | K26: =E26/E25-1 -> 0.024994626 | L26: =B26/B25-1 -> 0.013630242 | N26: 34.983266 | O26: 10.501961 | P26: 3.236842 | Q26: 0.29290911 | R26: 0.40415677 | S26: 0.090247193 | T26: =SUM(N26:S26) -> 49.509382 | U26: =T26/E26*1000000 -> 9439.3484 | V26: =N26/E26*1000000 -> 6669.8314 | W26: =O26/E26*1000000 -> 2002.2805
A28: (*) Vehicles live in the fleet at Dec 31st, from Tab 1.1
A29: Light travel excludes motorcycles/power cycles/mopeds
A30: (**) Infoshare DPE056AA, June population

Sheet 1.4b
B1: Regional annual VKT in billion | L1: Back to Contents
B2: Northland | C2: Auckland | D2: Gisborne | E2: Hawkes Bay | F2: Taranaki | G2: Manawatu/Wanganui | H2: Wellington | I2: Nelson/Marlborough | J2: Canterbury | K2: Southland | L2: Other or unknown regions | M2: NZ total
A3: 2001 | B3: 1.52 | C3: 11.26 | D3: 0.37 | E3: 1.32 | F3: 0.96 | G3: 2.12 | H3: 3.66 | I3: 1.18 | J3: 4.96 | K3: 1 | L3: 8.22 | M3: 36.57
A4: 2002 | B4: 1.44 | C4: 11.63 | D4: 0.38 | E4: 1.36 | F4: 0.99 | G4: 2.14 | H4: 3.72 | I4: 1.23 | J4: 5.22 | K4: 0.99 | L4: 8.67 | M4: 37.77
A5: 2003 | B5: 1.47 | C5: 12.06 | D5: 0.38 | E5: 1.4 | F5: 1.01 | G5: 2.18 | H5: 3.78 | I5: 1.28 | J5: 5.43 | K5: 1.01 | L5: 8.95 | M5: 38.94
A6: 2004 | B6: 1.53 | C6: 12.35 | D6: 0.39 | E6: 1.44 | F6: 1.03 | G6: 2.23 | H6: 3.86 | I6: 1.34 | J6: 5.6 | K6: 1.02 | L6: 9.28 | M6: 40.08
A7: 2005 | B7: 1.58 | C7: 12.47 | D7: 0.39 | E7: 1.45 | F7: 1.05 | G7: 2.23 | H7: 3.85 | I7: 1.35 | J7: 5.61 | K7: 1.02 | L7: 9.5 | M7: 40.5
A8: 2006 | B8: 1.6 | C8: 12.45 | D8: 0.39 | E8: 1.45 | F8: 1.05 | G8: 2.22 | H8: 3.81 | I8: 1.34 | J8: 5.61 | K8: 1.02 | L8: 9.57 | M8: 40.51
A9: 2007 | B9: 1.62 | C9: 12.55 | D9: 0.4 | E9: 1.48 | F9: 1.08 | G9: 2.26 | H9: 3.85 | I9: 1.39 | J9: 5.74 | K9: 1.04 | L9: 9.72 | M9: 41.12
A10: 2008 | B10: 1.6 | C10: 12.36 | D10: 0.38 | E10: 1.45 | F10: 1.08 | G10: 2.21 | H10: 3.76 | I10: 1.37 | J10: 5.7 | K10: 1.05 | L10: 9.61 | M10: 40.56
A11: 2009 | B11: 1.58 | C11: 12.32 | D11: 0.38 | E11: 1.44 | F11: 1.09 | G11: 2.2 | H11: 3.76 | I11: 1.35 | J11: 5.74 | K11: 1.06 | L11: 9.59 | M11: 40.52
A12: 2010 | B12: 1.57 | C12: 12.36 | D12: 0.38 | E12: 1.43 | F12: 1.09 | G12: 2.18 | H12: 3.77 | I12: 1.34 | J12: 5.72 | K12: 1.06 | L12: 9.6 | M12: 40.49
A13: 2011 | B13: 1.54 | C13: 12.33 | D13: 0.37 | E13: 1.4 | F13: 1.06 | G13: 2.12 | H13: 3.7 | I13: 1.33 | J13: 5.63 | K13: 1.04 | L13: 9.5 | M13: 40.02
A14: 2012 | B14: 1.53 | C14: 12.5 | D14: 0.36 | E14: 1.39 | F14: 1.06 | G14: 2.1 | H14: 3.66 | I14: 1.31 | J14: 5.76 | K14: 1.04 | L14: 9.38 | M14: 40.09
... A25: 2023 | B25: 1.91 | C25: 15.28 | D25: 0.43 | E25: 1.71 | F25: 1.22 | G25: 2.55 | H25: 4.27 | I25: 1.66 | J25: 7.25 | K25: 1.2 | L25: 12.03 | M25: 49.51

Sheet 1.5b
B1: Light fleet regional ownership | L1: Back to Contents
A3: Light vehicles
B4: Unknown | C4: Northland | D4: Auckland | E4: Waikato | F4: Bay of Plenty | G4: Gisborne | H4: Hawkes Bay | I4: Taranaki | J4: Manawatu-Whanganui | K4: Wellington | L4: Nelson/Marlborough | M4: Canterbury | N4: West Coast | O4: Otago | P4: Southland | Q4: Chathams | R4: Total
A5: 2001 | B5: 28670 | C5: 94961 | D5: 762231 | E5: 233070 | F5: 182171 | G5: 25959 | H5: 95771 | I5: 67303 | J5: 148004 | K5: 256603 | L5: 92894 | M5: 374836 | N5: 19118 | O5: 112961 | P5: 68935 | Q5: 164 | R5: 2563651
A6: 2002 | B6: 23384 | C6: 91718 | D6: 792176 | E6: 246817 | F6: 188840 | G6: 26505 | H6: 98392 | I6: 69737 | J6: 151056 | K6: 262958 | L6: 97130 | M6: 390377 | N6: 19932 | O6: 117532 | P6: 71291 | Q6: 167 | R6: 2648012
A7: 2003 | B7: 20384 | C7: 94422 | D7: 838200 | E7: 256257 | F7: 196112 | G7: 27104 | H7: 101922 | I7: 71566 | J7: 154361 | K7: 270763 | L7: 102241 | M7: 409412 | N7: 20644 | O7: 123126 | P7: 72803 | Q7: 163 | R7: 2759480
A8: 2004 | B8: 18443 | C8: 99324 | D8: 870517 | E8: 267820 | F8: 204638 | G8: 28251 | H8: 105262 | I8: 73628 | J8: 158631 | K8: 279287 | L8: 109180 | M8: 426768 | N8: 21680 | O8: 128923 | P8: 74557 | Q8: 170 | R8: 2867079
A9: 2005 | B9: 17088 | C9: 104820 | D9: 901126 | E9: 279388 | F9: 212791 | G9: 29230 | H9: 108935 | I9: 76815 | J9: 162552 | K9: 288481 | L9: 112497 | M9: 440975 | N9: 22458 | O9: 133876 | P9: 76007 | Q9: 163 | R9: 2967202
A10: 2006 | B10: 16027 | C10: 110053 | D10: 914669 | E10: 286100 | F10: 218020 | G10: 30059 | H10: 111324 | I10: 78941 | J10: 166734 | K10: 293668 | L10: 115510 | M10: 451172 | N10: 23372 | O10: 136770 | P10: 77280 | Q10: 168 | R10: 3029867
A11: 2007 | B11: 15139 | C11: 111447 | D11: 934960 | E11: 292261 | F11: 222828 | G11: 30512 | H11: 113247 | I11: 80879 | J11: 168805 | K11: 297016 | L11: 118983 | M11: 460204 | N11: 24007 | O11: 139863 | P11: 78571 | Q11: 164 | R11: 3088886
A12: 2008 | B12: 14466 | C12: 112414 | D12: 937133 | E12: 295255 | F12: 223944 | G12: 30340 | H12: 113546 | I12: 82703 | J12: 169065 | K12: 297375 | L12: 120453 | M12: 464998 | N12: 24711 | O12: 142033 | P12: 80352 | Q12: 164 | R12: 3108952
A13: 2009 | B13: 13744 | C13: 111917 | D13: 936640 | E13: 293748 | F13: 223389 | G13: 30012 | H13: 112816 | I13: 82894 | J13: 167583 | K13: 296429 | L13: 117957 | M13: 464957 | N13: 25384 | O13: 141505 | P13: 81117 | Q13: 169 | R13: 3100261
A14: 2010 | B14: 13193 | C14: 111570 | D14: 951811 | E14: 295687 | F14: 223699 | G14: 30000 | H14: 112519 | I14: 83014 | J14: 166995 | K14: 298107 | L14: 118071 | M14: 468336 | N14: 25560 | O14: 142950 | P14: 81250 | Q14: 157 | R14: 3122919
A15: 2011 | B15: 12820 | C15: 110505 | D15: 955307 | E15: 296349 | F15: 223071 | G15: 29679 | H15: 111379 | I15: 83109 | J15: 165102 | K15: 296574 | L15: 118441 | M15: 464953 | N15: 25737 | O15: 143713 | P15: 81275 | Q15: 149 | R15: 3118163
A16: 2012 | B16: 12514 | C16: 111336 | D16: 980319 | E16: 296961 | F16: 225355 | G16: 29732 | H16: 112003 | I16: 84028 | J16: 166319 | K16: 299531 | L16: 119568 | M16: 475275 | N16: 26112 | O16: 145021 | P16: 82123 | Q16: 149 | R16: 3166346
... A27: 2023 | B27: 10906 | C27: 157847 | D27: 1332384 | E27: 413105 | F27: 312306 | G27: 37664 | H27: 147518 | I27: 106737 | J27: 217175 | K27: 383041 | L27: 162547 | M27: 644328 | N27: 30734 | O27: 205970 | P27: 102514 | Q27: 204 | R27: 4264980
A28: NZ total includes the Chathams and unknown regions
A30: Population
C31: Northland | D31: Auckland | E31: Waikato | F31: Bay of Plenty | G31: Gisborne | H31: Hawke's Bay | I31: Taranaki | J31: Manawatu-Whanganui | K31: Wellington | L31: Nelson - Marlborough - Tasman | M31: Canterbury | N31: West Coast | O31: Otago | P31: Southland | Q31: Chatham Islands Territory | R31: NZ
A32: 2001 | C32: 144400 | D32: 1218300 | E32: 368400 | F32: 246900 | G32: 45500 | H32: 147300 | I32: 105700 | J32: 227500 | K32: 440200 | L32: 126000 | M32: 496700 | N32: 31100 | O32: 188300 | P32: 93300 | Q32: 750 | R32: 3880500
A33: 2002 | C33: 146000 | D33: 1255800 | E33: 373400 | F33: 250700 | G33: 45500 | H33: 148500 | I33: 105900 | J33: 227800 | K33: 445800 | L33: 127500 | M33: 505100 | N33: 31100 | O33: 191000 | P33: 93500 | Q33: 730 | R33: 3948500
A34: 2003 | C34: 147900 | D34: 1297600 | E34: 379200 | F34: 255000 | G34: 45800 | H34: 149400 | I34: 106600 | J34: 228700 | K34: 452300 | L34: 129500 | M34: 515500 | N34: 31400 | O34: 193500 | P34: 94100 | Q34: 710 | R34: 4027200
A35: 2004 | C35: 149500 | D35: 1326000 | E35: 384500 | F35: 259100 | G35: 45800 | H35: 150400 | I35: 106800 | J35: 229200 | K35: 457800 | L35: 131500 | M35: 524800 | N35: 31500 | O35: 195900 | P35: 94100 | Q35: 690 | R35: 4087500
A36: 2005 | C36: 151000 | D36: 1348900 | E36: 388700 | F36: 262200 | G36: 45900 | H36: 151200 | I36: 106800 | J36: 228900 | K36: 461600 | L36: 132600 | M36: 531900 | N36: 31800 | O36: 197900 | P36: 93700 | Q36: 670 | R36: 4133900
A37: 2006 | C37: 152700 | D37: 1373000 | E37: 393200 | F37: 265300 | G37: 46000 | H37: 152100 | I37: 107300 | J37: 229400 | K37: 466300 | L37: 133700 | M37: 540000 | N37: 32100 | O37: 199800 | P37: 93200 | Q37: 650 | R37: 4184600
A38: 2007 | C38: 154700 | D38: 1390400 | E38: 397300 | F38: 267900 | G38: 46000 | H38: 152900 | I38: 107600 | J38: 228700 | K38: 469300 | L38: 134700 | M38: 547400 | N38: 32300 | O38: 201000 | P38: 93100 | Q38: 640 | R38: 4223800
A39: 2008 | C39: 156300 | D39: 1405500 | E39: 401600 | F39: 270200 | G39: 46000 | H39: 153500 | I39: 108300 | J39: 228600 | K39: 471800 | L39: 135900 | M39: 553800 | N39: 32400 | O39: 202100 | P39: 93300 | Q39: 640 | R39: 4259800
A40: 2009 | C40: 158200 | D40: 1421700 | E40: 406600 | F40: 272700 | G40: 46300 | H40: 154500 | I40: 109300 | J40: 229300 | K40: 475600 | L40: 137100 | M40: 560600 | N40: 32700 | O40: 203300 | P40: 93900 | Q40: 640 | R40: 4302600
A41: 2010 | C41: 160600 | D41: 1439600 | E41: 412400 | F41: 275700 | G41: 46700 | H41: 156300 | I41: 110700 | J41: 230400 | K41: 479400 | L41: 138500 | M41: 567700 | N41: 32800 | O41: 204600 | P41: 94700 | Q41: 640 | R41: 4350700
A42: 2011 | C42: 162500 | D42: 1459600 | E42: 417300 | F42: 278200 | G42: 46800 | H42: 157300 | I42: 111800 | J42: 231300 | K42: 483400 | L42: 140400 | M42: 559300 | N42: 33100 | O42: 206600 | P42: 95700 | Q42: 640 | R42: 4384000
A43: 2012 | C43: 163500 | D43: 1476500 | E43: 421500 | F43: 278800 | G43: 47000 | H43: 157500 | I43: 112700 | J43: 231200 | K43: 485100 | L43: 141400 | M43: 556000 | N43: 33100 | O43: 207400 | P43: 95900 | Q43: 600 | R43: 4408100
... A54: 2023 | C54: 203900 | D54: 1739300 | E54: 522600 | F54: 354100 | G54: 52600 | H54: 184800 | I54: 128700 | J54: 260900 | K54: 550500 | L54: 167200 | M54: 666300 | N54: 32900 | O54: 254600 | P54: 103900 | Q54: 730 | R54: 5223100
A55: Infoshare DPE051AA for regions and NZ total and DPE052AA for the Chatham Islands Territory, June population
A57: Light vehicles per 1000 popn
C58: Northland | D58: Auckland | E58: Waikato | F58: Bay of Plenty | G58: Gisborne | H58: Hawke's Bay | I58: Taranaki | J58: Manawatu-Whanganui | K58: Wellington | L58: Nelson - Marl | M58: Canterbury | N58: West Coast | O58: Otago | P58: Southland | Q58: Chatham Islands Territory | R58: NZ
A59: 2001 | C59: =C5*1000/C32 -> 657.62465 | D59: =D5*1000/D32 -> 625.65132 | E59: =E5*1000/E32 -> 632.65472 | F59: =F5*1000/F32 -> 737.83313 | G59: =G5*1000/G32 -> 570.52747 | H59: =H5*1000/H32 -> 650.17651 | I59: =I5*1000/I32 -> 636.73605 | J59: =J5*1000/J32 -> 650.56703 | ... R59: =R5*1000/R32 -> 660.64966
A60: 2002 | C60: =C6*1000/C33 -> 628.20548 | D60: =D6*1000/D33 -> 630.81382 | E60: =E6*1000/E33 -> 660.99893 | F60: =F6*1000/F33 -> 753.2509 | G60: =G6*1000/G33 -> 582.52747 | H60: =H6*1000/H33 -> 662.57239 | I60: =I6*1000/I33 -> 658.51747 | J60: =J6*1000/J33 -> 663.10799 | ... R60: =R6*1000/R33 -> 670.63746
A61: 2003 | C61: =C7*1000/C34 -> 638.41785 | D61: =D7*1000/D34 -> 645.96178 | E61: =E7*1000/E34 -> 675.78323 | F61: =F7*1000/F34 -> 769.06667 | G61: =G7*1000/G34 -> 591.79039 | H61: =H7*1000/H34 -> 682.20884 | I61: =I7*1000/I34 -> 671.35084 | J61: =J7*1000/J34 -> 674.94972 | ... R61: =R7*1000/R34 -> 685.21057
A62: 2004 | C62: =C8*1000/C35 -> 664.37458 | D62: =D8*1000/D35 -> 656.49849 | E62: =E8*1000/E35 -> 696.54096 | F62: =F8*1000/F35 -> 789.80316 | G62: =G8*1000/G35 -> 616.83406 | H62: =H8*1000/H35 -> 699.88032 | I62: =I8*1000/I35 -> 689.40075 | J62: =J8*1000/J35 -> 692.10733 | ... R62: =R8*1000/R35 -> 701.42606
A63: 2005 | C63: =C9*1000/C36 -> 694.17219 | D63: =D9*1000/D36 -> 668.04507 | E63: =E9*1000/E36 -> 718.77541 | F63: =F9*1000/F36 -> 811.55988 | G63: =G9*1000/G36 -> 636.81917 | H63: =H9*1000/H36 -> 720.46958 | I63: =I9*1000/I36 -> 719.24157 | J63: =J9*1000/J36 -> 710.14417 | ... R63: =R9*1000/R36 -> 717.77305
...

Sheet 2.1, 2.2, 2.3,2.4
B1: Fleet composition by vehcle type and import status | O1: Average vehicle ages | AH1: Back to Contents
B2: Vehicles | O2: Vehicle ages | Z2: Calculated summaries
A3: Period | B3: Total light new | C3: Total light used import | D3: Total LPV new | E3: Total LPV used | F3: Total LCV new | G3: Total LCV used | H3: Total MC new | I3: Total MC used | J3: Total truck new | K3: Total truck used | L3: Total bus new | M3: Total bus used | O3: Light passenger New | P3: Light passenger used import | Q3: Light commercial New | R3: Light commercial used import | S3: Motorcycle New | T3: Motorcycle Used Import | U3: Truck New | V3: Truck Used Import | W3: Bus New | X3: Bus Used Import | Z3: Light used % | AA3: Truck used % | AB3: Bus used % | AC3: Light fleet average age | AD3: Light passenger average age | AE3: Light commercial average age | AF3: Motorcycle average age | AG3: Truck fleet average age | AH3: Bus fleet average age | AI3: Light used average age | AJ3: New light average age
A4: 2000 | B4: 1513147 | C4: 981708 | D4: 1264812 | E4: 882704 | F4: 248335 | G4: 99004 | H4: 53126 | I4: 25515 | J4: 70002 | K4: 25620 | L4: 3330 | M4: 1082 | O4: 11.989769 | P4: 11.347843 | Q4: 12.085115 | R4: 13.319553 | S4: 14.510955 | T4: 19.699647 | U4: 14.773921 | V4: 13.084504 | W4: 16.554054 | X4: 15.019409 | Z4: =C4/(B4+C4) -> 0.39349301 | AA4: =K4/(J4+K4) -> 0.26792997 | AB4: =M4/(L4+M4) -> 0.24524025 | AC4: =(D4*O4+E4*P4+F4*Q4+G4*R4)/SUM(D4:G4) -> 11.82491 | AD4: =(D4*O4+E4*P4)/(D4+E4) -> 11.725915 | AE4: =(F4*Q4+G4*R4)/(F4+G4) -> 12.436974 | AF4: =(H4*S4+I4*T4)/(H4+I4) -> 16.194421 | AG4: =(J4*U4+K4*V4)/(J4+K4) -> 14.321275 | AH4: =(L4*W4+M4*X4)/(L4+M4) -> 16.177697 | AI4: =(E4*P4+G4*R4)/SUM(E4,G4) -> 11.546687 | AJ4: =(D4*O4+F4*Q4)/SUM(D4,F4) -> 12.005417
A5: 2001 | B5: 1496688 | C5: 1066963 | D5: 1245148 | E5: 968524 | F5: 251540 | G5: 98439 | H5: 53618 | I5: 25612 | J5: 70085 | K5: 27782 | L5: 3444 | M5: 1254 | O5: 12.069625 | P5: 11.62803 | Q5: 12.109334 | R5: 13.933212 | S5: 14.75981 | T5: 20.432766 | U5: 15.025961 | V5: 13.567814 | W5: 16.652149 | X5: 15.333333 | Z5: =C5/(B5+C5) -> 0.41618887 | AA5: =K5/(J5+K5) -> 0.28387505 | AB5: =M5/(L5+M5) -> 0.26692209 | AC5: =(D5*O5+E5*P5+F5*Q5+G5*R5)/SUM(D5:G5) -> 11.978248 | AD5: =(D5*O5+E5*P5)/(D5+E5) -> 11.876418 | AE5: =(F5*Q5+G5*R5)/(F5+G5) -> 12.622339 | AF5: =(H5*S5+I5*T5)/(H5+I5) -> 16.593658 | AG5: =(J5*U5+K5*V5)/(J5+K5) -> 14.61203 | AH5: =(L5*W5+M5*X5)/(L5+M5) -> 16.300128 | AI5: =(E5*P5+G5*R5)/SUM(E5,G5) -> 11.840708 | AJ5: =(D5*O5+F5*Q5)/SUM(D5,F5) -> 12.076298
A6: 2002 | B6: 1491314 | C6: 1156698 | D6: 1235091 | E6: 1057292 | F6: 256223 | G6: 99406 | H6: 54626 | I6: 26134 | J6: 70739 | K6: 30962 | L6: 3524 | M6: 1560 | O6: 12.08289 | P6: 11.839018 | Q6: 12.061571 | R6: 14.364797 | S6: 14.836076 | T6: 20.962424 | U6: 15.104878 | V6: 13.865642 | W6: 16.688138 | X6: 15.467308 | Z6: =C6/(B6+C6) -> 0.43681751 | AA6: =K6/(J6+K6) -> 0.30444145 | AB6: =M6/(L6+M6) -> 0.306845 | AC6: =(D6*O6+E6*P6+F6*Q6+G6*R6)/SUM(D6:G6) -> 12.069117 | AD6: =(D6*O6+E6*P6)/(D6+E6) -> 11.970411 | AE6: =(F6*Q6+G6*R6)/(F6+G6) -> 12.705373 | AF6: =(H6*S6+I6*T6)/(H6+I6) -> 16.818567 | AG6: =(J6*U6+K6*V6)/(J6+K6) -> 14.727603 | AH6: =(L6*W6+M6*X6)/(L6+M6) -> 16.313533 | AI6: =(E6*P6+G6*R6)/SUM(E6,G6) -> 12.056082 | AJ6: =(D6*O6+F6*Q6)/SUM(D6,F6) -> 12.079227
A7: 2003 | B7: 1497748 | C7: 1261732 | D7: 1234787 | E7: 1160343 | F7: 262961 | G7: 101389 | H7: 56702 | I7: 26921 | J7: 71839 | K7: 35031 | L7: 3657 | M7: 1794 | O7: 12.04329 | P7: 12.003142 | Q7: 11.9433 | R7: 14.721474 | S7: 14.669006 | T7: 21.347443 | U7: 15.080103 | V7: 14.128814 | W7: 16.426716 | X7: 15.869008 | Z7: =C7/(B7+C7) -> 0.45723542 | AA7: =K7/(J7+K7) -> 0.32779077 | AB7: =M7/(L7+M7) -> 0.32911392 | AC7: =(D7*O7+E7*P7+F7*Q7+G7*R7)/SUM(D7:G7) -> 12.115282 | AD7: =(D7*O7+E7*P7)/(D7+E7) -> 12.02384 | AE7: =(F7*Q7+G7*R7)/(F7+G7) -> 12.716392 | AF7: =(H7*S7+I7*T7)/(H7+I7) -> 16.819015 | AG7: =(J7*U7+K7*V7)/(J7+K7) -> 14.768279 | AH7: =(L7*W7+M7*X7)/(L7+M7) -> 16.243166 | AI7: =(E7*P7+G7*R7)/SUM(E7,G7) -> 12.221579 | AJ7: =(D7*O7+F7*Q7)/SUM(D7,F7) -> 12.025735
A8: 2004 | B8: 1510913 | C8: 1356166 | D8: 1238985 | E8: 1251926 | F8: 271928 | G8: 104240 | H8: 60545 | I8: 27921 | J8: 73545 | K8: 40206 | L8: 3868 | M8: 2008 | O8: 11.961607 | P8: 12.250095 | Q8: 11.769853 | R8: 15.00778 | S8: 14.12162 | T8: 21.558057 | U8: 14.959256 | V8: 14.370094 | W8: 16.044984 | X8: 16.194223 | Z8: =C8/(B8+C8) -> 0.47301313 | AA8: =K8/(J8+K8) -> 0.35345623 | AB8: =M8/(L8+M8) -> 0.34172907 | AC8: =(D8*O8+E8*P8+F8*Q8+G8*R8)/SUM(D8:G8) -> 12.180142 | AD8: =(D8*O8+E8*P8)/(D8+E8) -> 12.106601 | AE8: =(F8*Q8+G8*R8)/(F8+G8) -> 12.667115 | AF8: =(H8*S8+I8*T8)/(H8+I8) -> 16.468655 | AG8: =(J8*U8+K8*V8)/(J8+K8) -> 14.751013 | AH8: =(L8*W8+M8*X8)/(L8+M8) -> 16.095984 | AI8: =(E8*P8+G8*R8)/SUM(E8,G8) -> 12.462061 | AJ8: =(D8*O8+F8*Q8)/SUM(D8,F8) -> 11.927096
A9: 2005 | B9: 1529850 | C9: 1437352 | D9: 1247345 | E9: 1331171 | F9: 282505 | G9: 106181 | H9: 67835 | I9: 29563 | J9: 75364 | K9: 44455 | L9: 4006 | M9: 2199 | O9: 11.869024 | P9: 12.559071 | Q9: 11.582209 | R9: 15.301273 | S9: 13.113481 | T9: 21.577157 | U9: 14.748408 | V9: 14.762918 | W9: 15.957439 | X9: 16.58231 | Z9: =C9/(B9+C9) -> 0.48441326 | AA9: =K9/(J9+K9) -> 0.37101795 | AB9: =M9/(L9+M9) -> 0.35439162 | AC9: =(D9*O9+E9*P9+F9*Q9+G9*R9)/SUM(D9:G9) -> 12.274114 | AD9: =(D9*O9+E9*P9)/(D9+E9) -> 12.225264 | AE9: =(F9*Q9+G9*R9)/(F9+G9) -> 12.598181 | AF9: =(H9*S9+I9*T9)/(H9+I9) -> 15.682442 | AG9: =(J9*U9+K9*V9)/(J9+K9) -> 14.753791 | AH9: =(L9*W9+M9*X9)/(L9+M9) -> 16.178888 | AI9: =(E9*P9+G9*R9)/SUM(E9,G9) -> 12.761644 | AJ9: =(D9*O9+F9*Q9)/SUM(D9,F9) -> 11.81606
A10: 2006 | B10: 1549302 | C10: 1480565 | D10: 1257678 | E10: 1373983 | F10: 291624 | G10: 106582 | H10: 76237 | I10: 31819 | J10: 76298 | K10: 48051 | L10: 4068 | M10: 2381 | O10: 11.80853 | P10: 12.969406 | Q10: 11.501128 | R10: 15.652427 | S10: 12.292968 | T10: 21.523634 | U10: 14.767104 | V10: 15.219298 | W10: 16.201819 | X10: 17.142167 | Z10: =C10/(B10+C10) -> 0.48865676 | AA10: =K10/(J10+K10) -> 0.38642048 | AB10: =M10/(L10+M10) -> 0.36920453 | AC10: =(D10*O10+E10*P10+F10*Q10+G10*R10)/SUM(D10:G10) -> 12.440594 | AD10: =(D10*O10+E10*P10)/(D10+E10) -> 12.41462 | AE10: =(F10*Q10+G10*R10)/(F10+G10) -> 12.612246 | AF10: =(H10*S10+I10*T10)/(H10+I10) -> 15.011101 | AG10: =(J10*U10+K10*V10)/(J10+K10) -> 14.941841 | AH10: =(L10*W10+M10*X10)/(L10+M10) -> 16.549 | AI10: =(E10*P10+G10*R10)/SUM(E10,G10) -> 13.16255 | AJ10: =(D10*O10+F10*Q10)/SUM(D10,F10) -> 11.750668
A11: 2007 | B11: 1573227 | C11: 1515659 | D11: 1271123 | E11: 1408225 | F11: 302104 | G11: 107434 | H11: 85419 | I11: 34365 | J11: 77439 | K11: 51377 | L11: 4173 | M11: 2708 | O11: 11.75978 | P11: 13.366922 | Q11: 11.410918 | R11: 15.890147 | S11: 11.553524 | T11: 21.325753 | U11: 14.754136 | V11: 15.659429 | W11: 16.163072 | X11: 17.263294 | Z11: =C11/(B11+C11) -> 0.49068143 | AA11: =K11/(J11+K11) -> 0.39884021 | AB11: =M11/(L11+M11) -> 0.39354745 | AC11: =(D11*O11+E11*P11+F11*Q11+G11*R11)/SUM(D11:G11) -> 12.602014 | AD11: =(D11*O11+E11*P11)/(D11+E11) -> 12.604469 | AE11: =(F11*Q11+G11*R11)/(F11+G11) -> 12.585953 | AF11: =(H11*S11+I11*T11)/(H11+I11) -> 14.357093 | AG11: =(J11*U11+K11*V11)/(J11+K11) -> 15.115203 | AH11: =(L11*W11+M11*X11)/(L11+M11) -> 16.596062 | AI11: =(E11*P11+G11*R11)/SUM(E11,G11) -> 13.545775 | AJ11: =(D11*O11+F11*Q11)/SUM(D11,F11) -> 11.692788
A12: 2008 | B12: 1593815 | C12: 1515137 | D12: 1283022 | E12: 1409926 | F12: 310793 | G12: 105211 | H12: 96247 | I12: 37438 | J12: 78702 | K12: 52557 | L12: 4362 | M12: 2967 | O12: 11.7704 | P12: 13.845048 | Q12: 11.416193 | R12: 16.298605 | S12: 10.873731 | T12: 21.138562 | U12: 14.693667 | V12: 16.279649 | W12: 15.727877 | X12: 17.631109 | Z12: =C12/(B12+C12) -> 0.48734654 | AA12: =K12/(J12+K12) -> 0.40040683 | AB12: =M12/(L12+M12) -> 0.40483013 | AC12: =(D12*O12+E12*P12+F12*Q12+G12*R12)/SUM(D12:G12) -> 12.829095 | AD12: =(D12*O12+E12*P12)/(D12+E12) -> 12.856607 | AE12: =(F12*Q12+G12*R12)/(F12+G12) -> 12.650997 | AF12: =(H12*S12+I12*T12)/(H12+I12) -> 13.74836 | AG12: =(J12*U12+K12*V12)/(J12+K12) -> 15.328705 | AH12: =(L12*W12+M12*X12)/(L12+M12) -> 16.498363 | AI12: =(E12*P12+G12*R12)/SUM(E12,G12) -> 14.015423 | AJ12: =(D12*O12+F12*Q12)/SUM(D12,F12) -> 11.70133
A13: 2009 | B13: 1599514 | C13: 1500747 | D13: 1285510 | E13: 1399353 | F13: 314004 | G13: 101394 | H13: 100004 | I13: 38530 | J13: 78263 | K13: 52142 | L13: 4663 | M13: 3034 | O13: 12.007329 | P13: 14.384134 | Q13: 11.70786 | R13: 16.923289 | S13: 11.100166 | T13: 21.627745 | U13: 14.988404 | V13: 17.048042 | W13: 15.013832 | X13: 18.275214 | Z13: =C13/(B13+C13) -> 0.48407118 | AA13: =K13/(J13+K13) -> 0.39984663 | AB13: =M13/(L13+M13) -> 0.39417955 | AC13: =(D13*O13+E13*P13+F13*Q13+G13*R13)/SUM(D13:G13) -> 13.210583 | AD13: =(D13*O13+E13*P13)/(D13+E13) -> 13.246121 | AE13: =(F13*Q13+G13*R13)/(F13+G13) -> 12.980888 | AF13: =(H13*S13+I13*T13)/(H13+I13) -> 14.028166 | AG13: =(J13*U13+K13*V13)/(J13+K13) -> 15.811944 | AH13: =(L13*W13+M13*X13)/(L13+M13) -> 16.299402 | AI13: =(E13*P13+G13*R13)/SUM(E13,G13) -> 14.555685 | AJ13: =(D13*O13+F13*Q13)/SUM(D13,F13) -> 11.948539
A14: 2010 | B14: 1617581 | C14: 1505338 | D14: 1297750 | E14: 1407707 | F14: 319831 | G14: 97631 | H14: 101482 | I14: 38890 | J14: 77608 | K14: 51436 | L14: 4796 | M14: 3036 | O14: 12.172967 | P14: 14.81083 | Q14: 11.876801 | R14: 17.52658 | S14: 11.521797 | T14: 22.169401 | U14: 15.249233 | V14: 17.8301 | W14: 14.933903 | X14: 19.00527 | Z14: =C14/(B14+C14) -> 0.48202915 | AA14: =K14/(J14+K14) -> 0.39859273 | AB14: =M14/(L14+M14) -> 0.38764045 | AC14: =(D14*O14+E14*P14+F14*Q14+G14*R14)/SUM(D14:G14) -> 13.499064 | AD14: =(D14*O14+E14*P14)/(D14+E14) -> 13.545504 | AE14: =(F14*Q14+G14*R14)/(F14+G14) -> 13.198103 | AF14: =(H14*S14+I14*T14)/(H14+I14) -> 14.471711 | AG14: =(J14*U14+K14*V14)/(J14+K14) -> 16.277948 | AH14: =(L14*W14+M14*X14)/(L14+M14) -> 16.51213 | AI14: =(E14*P14+G14*R14)/SUM(E14,G14) -> 14.986964 | AJ14: =(D14*O14+F14*Q14)/SUM(D14,F14) -> 12.114408
A15: 2011 | B15: 1632753 | C15: 1485410 | D15: 1306679 | E15: 1391812 | F15: 326074 | G15: 93598 | H15: 102086 | I15: 38898 | J15: 77537 | K15: 50286 | L15: 4950 | M15: 2989 | O15: 12.303188 | P15: 15.256154 | Q15: 11.968634 | R15: 18.064243 | S15: 11.985571 | T15: 22.883953 | U15: 15.406238 | V15: 18.607366 | W15: 14.568485 | X15: 19.796755 | Z15: =C15/(B15+C15) -> 0.47637343 | AA15: =K15/(J15+K15) -> 0.39340338 | AB15: =M15/(L15+M15) -> 0.37649578 | AC15: =(D15*O15+E15*P15+F15*Q15+G15*R15)/SUM(D15:G15) -> 13.759208 | AD15: =(D15*O15+E15*P15)/(D15+E15) -> 13.826252 | AE15: =(F15*Q15+G15*R15)/(F15+G15) -> 13.328117 | AF15: =(H15*S15+I15*T15)/(H15+I15) -> 14.992474 | AG15: =(J15*U15+K15*V15)/(J15+K15) -> 16.665573 | AH15: =(L15*W15+M15*X15)/(L15+M15) -> 16.536906 | AI15: =(E15*P15+G15*R15)/SUM(E15,G15) -> 15.433096 | AJ15: =(D15*O15+F15*Q15)/SUM(D15,F15) -> 12.236375
... A27: 2023 | B27: 2482946 | C27: 1782034 | D27: 1846155 | E27: 1663800 | F27: 636791 | G27: 118234 | H27: 150080 | I27: 53103 | J27: 117414 | K27: 53454 | L27: 8782 | M27: 2737 | O27: 12.316759 | P27: 17.939554 | Q27: 11.426989 | R27: 20.054096 | S27: 14.728585 | T27: 29.654492 | U27: 15.128307 | V27: 23.757941 | W27: 13.923024 | X27: 26.049141 | Z27: =C27/(B27+C27) -> 0.41782939 | AA27: =K27/(J27+K27) -> 0.31283798 | AB27: =M27/(L27+M27) -> 0.23760743 | AC27: =(D27*O27+E27*P27+F27*Q27+G27*R27)/SUM(D27:G27) -> 14.591899 | AD27: =(D27*O27+E27*P27)/(D27+E27) -> 14.982094 | AE27: =(F27*Q27+G27*R27)/(F27+G27) -> 12.777961 | AF27: =(H27*S27+I27*T27)/(H27+I27) -> 18.629553 | AG27: =(J27*U27+K27*V27)/(J27+K27) -> 17.827984 | AH27: =(L27*W27+M27*X27)/(L27+M27) -> 16.80428 | AI27: =(E27*P27+G27*R27)/SUM(E27,G27) -> 18.079849 | AJ27: =(D27*O27+F27*Q27)/SUM(D27,F27) -> 12.088563

Sheet 2.5a-2.8a
B1: Vehicle Year of Manufacture (by end of 2023) | J1: Back to Contents
A2: Year of manufacture | B2: Light passenger New | C2: Light passenger used import | D2: Light commercial New | E2: Light commercial used import | F2: Motorcycle New | G2: Motorcycle used | H2: Truck New | I2: Truck used | J2: Bus New | K2: Bus used | L2: Total Light
A3: 1968 | B3: 30812 | C3: 19434 | D3: 4471 | E3: 3004 | F3: 3432 | G3: 3773 | H3: 1521 | I3: 251 | J3: 93 | K3: 16 | L3: =SUM(B3:E3) -> 57721
A4: 1969 | B4: 2661 | C4: 1476 | D4: 290 | E4: 131 | F4: 153 | G4: 386 | H4: 153 | I4: 12 | J4: 6 | K4: 0 | L4: =SUM(B4:E4) -> 4558
A5: 1970 | B5: 3843 | C5: 1275 | D5: 499 | E5: 159 | F5: 211 | G5: 461 | H5: 205 | I5: 11 | J5: 11 | K5: 1 | L5: =SUM(B5:E5) -> 5776
A6: 1971 | B6: 4107 | C6: 922 | D6: 699 | E6: 156 | F6: 332 | G6: 573 | H6: 185 | I6: 19 | J6: 10 | K6: 2 | L6: =SUM(B6:E6) -> 5884
A7: 1972 | B7: 4703 | C7: 1041 | D7: 599 | E7: 182 | F7: 392 | G7: 702 | H7: 210 | I7: 10 | J7: 8 | K7: 2 | L7: =SUM(B7:E7) -> 6525
A8: 1973 | B8: 4875 | C8: 1039 | D8: 568 | E8: 128 | F8: 606 | G8: 818 | H8: 247 | I8: 10 | J8: 10 | K8: 0 | L8: =SUM(B8:E8) -> 6610
A9: 1974 | B9: 5173 | C9: 808 | D9: 579 | E9: 129 | F9: 502 | G9: 730 | H9: 211 | I9: 21 | J9: 20 | K9: 1 | L9: =SUM(B9:E9) -> 6689
A10: 1975 | B10: 3172 | C10: 501 | D10: 598 | E10: 124 | F10: 449 | G10: 812 | H10: 306 | I10: 31 | J10: 24 | K10: 0 | L10: =SUM(B10:E10) -> 4395
A11: 1976 | B11: 2557 | C11: 527 | D11: 698 | E11: 170 | F11: 343 | G11: 642 | H11: 365 | I11: 22 | J11: 31 | K11: 5 | L11: =SUM(B11:E11) -> 3952
A12: 1977 | B12: 2516 | C12: 585 | D12: 836 | E12: 203 | F12: 333 | G12: 515 | H12: 365 | I12: 25 | J12: 33 | K12: 5 | L12: =SUM(B12:E12) -> 4140
A13: 1978 | B13: 3046 | C13: 997 | D13: 978 | E13: 209 | F13: 323 | G13: 645 | H13: 331 | I13: 36 | J13: 45 | K13: 11 | L13: =SUM(B13:E13) -> 5230
A14: 1979 | B14: 2872 | C14: 1218 | D14: 1169 | E14: 239 | F14: 613 | G14: 913 | H14: 390 | I14: 54 | J14: 50 | K14: 5 | L14: =SUM(B14:E14) -> 5498
... A58: 2023 | B58: 110427 | C58: 144 | D58: 30477 | E58: 191 | F58: 8652 | G58: 17 | H58: 7638 | I58: 13 | J58: 296 | K58: 0 | L58: =SUM(B58:E58) -> 141239

Sheet 2.9
B1: Heavy vehicle mass distribution | F1: Back to Contents
A2: Gross vehicle mass range (kg) | B2: Used Import | C2: New | D2: Total
A3: Truck < 5000 | B3: 14715 | C3: 16015 | D3: =SUM(B3:C3) -> 30730
A4: Truck < 7500 | B4: 19774 | C4: 19857 | D4: =SUM(B4:C4) -> 39631
A5: Truck < 10000 | B5: 10157 | C5: 9834 | D5: =SUM(B5:C5) -> 19991
A6: Truck < 12000 | B6: 2079 | C6: 6799 | D6: =SUM(B6:C6) -> 8878
A7: Truck < 15000 | B7: 1664 | C7: 7260 | D7: =SUM(B7:C7) -> 8924
A8: Truck < 20000 | B8: 1511 | C8: 8090 | D8: =SUM(B8:C8) -> 9601
A9: Truck < 25000 | B9: 2128 | C9: 15102 | D9: =SUM(B9:C9) -> 17230
A10: Truck < 30000 | B10: 1098 | C10: 17631 | D10: =SUM(B10:C10) -> 18729
A11: Truck > 30000 | B11: 328 | C11: 16826 | D11: =SUM(B11:C11) -> 17154
A12: Bus < 7000 | B12: 1082 | C12: 1962 | D12: =SUM(B12:C12) -> 3044
A13: Bus < 12000 | B13: 615 | C13: 1837 | D13: =SUM(B13:C13) -> 2452
A14: Bus > 12000 | B14: 1040 | C14: 4983 | D14: =SUM(B14:C14) -> 6023

Sheet 2.10
B1: Light fleet age distribution | S1: Back to Contents
A2: Age | B2: 2000 | C2: 2001 | D2: 2002 | E2: 2003 | F2: 2004 | G2: 2005 | H2: 2006 | I2: 2007 | J2: 2008 | K2: 2009 | L2: 2010 | M2: 2011 | N2: 2012 | O2: 2013 | P2: 2014 | Q2: 2015 | R2: 2016 | S2: 2017 | T2: 2018 | U2: 2019 | V2: 2020 | W2: 2021 | X2: 2022 | Y2: 2023
A3: 0-4 years | B3: 375595 | C3: 361250 | D3: 371531 | E3: 397135 | F3: 422502 | G3: 451868 | H3: 475878 | I3: 498452 | J3: 503725 | K3: 471588 | L3: 448822 | M3: 425961 | N3: 423448 | O3: 443008 | P3: 502812 | Q3: 559017 | R3: 620490 | S3: 678018 | T3: 722241 | U3: 744907 | V3: 726794 | W3: 744176 | X3: 747672 | Y3: 724820
A4: 5-9 years | B4: 720474 | C4: 737637 | D4: 730120 | E4: 760009 | F4: 761874 | G4: 756371 | H4: 661006 | I4: 609593 | J4: 592820 | K4: 594274 | L4: 630826 | M4: 649291 | N4: 663849 | O4: 704429 | P4: 698844 | Q4: 665896 | R4: 629226 | S4: 606796 | T4: 603984 | U4: 663733 | V4: 707226 | W4: 779912 | X4: 833786 | Y4: 873157
A5: 10-14 years | B5: 785329 | C5: 829944 | D5: 887818 | E5: 907696 | F5: 926763 | G5: 938736 | H5: 1023134 | I5: 1052628 | J5: 1050466 | K5: 995716 | L5: 926404 | M5: 809545 | N5: 752883 | O5: 724455 | P5: 765832 | Q5: 854435 | R5: 961502 | S5: 1079686 | T5: 1176237 | U5: 1122720 | V5: 1016871 | W5: 910491 | X5: 835161 | Y5: 805956
A6: 15-19 years | B6: 393886 | C6: 404925 | D6: 419311 | E6: 446602 | F6: 488830 | G6: 536073 | H6: 572288 | I6: 616169 | J6: 627757 | K6: 661072 | L6: 687247 | M6: 768183 | N6: 808726 | O6: 813663 | P6: 774000 | Q6: 728896 | R6: 645377 | S6: 596437 | T6: 568450 | U6: 647352 | V6: 768897 | W6: 872464 | X6: 967658 | Y6: 1021004
A7: 20+ years | B7: 219561 | C7: 229885 | D7: 239222 | E7: 248029 | F7: 267101 | G7: 284145 | H7: 297552 | I7: 312035 | J7: 334176 | K7: 377603 | L7: 429612 | M7: 465175 | N7: 517433 | O7: 558506 | P7: 618272 | Q7: 675011 | R7: 774941 | S7: 822794 | T7: 829104 | U7: 817881 | V7: 818002 | W7: 818758 | X7: 823352 | Y7: 840043
A8: Total | B8: =SUM(B3:B7) -> 2494845 | C8: =SUM(C3:C7) -> 2563641 | D8: =SUM(D3:D7) -> 2648002 | E8: =SUM(E3:E7) -> 2759471 | F8: =SUM(F3:F7) -> 2867070 | G8: =SUM(G3:G7) -> 2967193 | H8: =SUM(H3:H7) -> 3029858 | I8: =SUM(I3:I7) -> 3088877 | ... Y8: =SUM(Y3:Y7) -> 4264980
A11: 0-4 years | B11: =B3/B$8 -> 0.15054843 | C11: =C3/C$8 -> 0.14091287 | D11: =D3/D$8 -> 0.14030616 | E11: =E3/E$8 -> 0.14391708 | F11: =F3/F$8 -> 0.14736368 | G11: =G3/G$8 -> 0.15228804 | H11: =H3/H$8 -> 0.15706281 | I11: =I3/I$8 -> 0.16136997 | ... Y11: =Y3/Y$8 -> 0.16994687
A12: 5-9 years | B12: =B4/B$8 -> 0.28878507 | C12: =C4/C$8 -> 0.28773022 | D12: =D4/D$8 -> 0.27572487 | E12: =E4/E$8 -> 0.27541837 | F12: =F4/F$8 -> 0.26573261 | G12: =G4/G$8 -> 0.25491129 | H12: =H4/H$8 -> 0.21816402 | I12: =I4/I$8 -> 0.19735101 | ... Y12: =Y4/Y$8 -> 0.2047271
A13: 10-14 years | B13: =B5/B$8 -> 0.31478068 | C13: =C5/C$8 -> 0.32373644 | D13: =D5/D$8 -> 0.33527845 | E13: =E5/E$8 -> 0.32893841 | F13: =F5/F$8 -> 0.32324394 | G13: =G5/G$8 -> 0.31637174 | H13: =H5/H$8 -> 0.33768381 | I13: =I5/I$8 -> 0.34078016 | ... Y13: =Y5/Y$8 -> 0.18897064
A14: 15-19 years | B14: =B6/B$8 -> 0.15787995 | C14: =C6/C$8 -> 0.15794918 | D14: =D6/D$8 -> 0.15834996 | E14: =E6/E$8 -> 0.16184334 | F14: =F6/F$8 -> 0.1704981 | G14: =G6/G$8 -> 0.18066671 | H14: =H6/H$8 -> 0.18888278 | I14: =I6/I$8 -> 0.19947994 | ... Y14: =Y6/Y$8 -> 0.23939245
A15: 20+ years | B15: =B7/B$8 -> 0.088005868 | C15: =C7/C$8 -> 0.089671292 | D15: =D7/D$8 -> 0.090340566 | E15: =E7/E$8 -> 0.089882807 | F15: =F7/F$8 -> 0.09316166 | G15: =G7/G$8 -> 0.095762224 | H15: =H7/H$8 -> 0.098206583 | I15: =I7/I$8 -> 0.10101891 | ... Y15: =Y7/Y$8 -> 0.19696294

Sheet 3.1,3.2,3.4,8.3
B1: Travel, by 5 year YoM bands | M1: Back to Contents
B2: Travel (million vkm) | M2: Number of vehicles with travel recorded during the year (*)
A3: YoM | B3: NZ New LPV | C3: Used LPV | D3: NZ New LCV | E3: Used LCV | F3: NZ New Heavy truck | G3: Used Import Heavy truck | H3: NZ New Bus | I3: Used Import Bus | J3: MCycle | K3: Light Petrol | L3: Light Diesel | M3: Light_petrol_veh | N3: Light_diesel_veh | O3: NZ New LPV | P3: Used LPV | Q3: NZ New LCV | R3: Used LCV | S3: Truck_new | T3: Truck_used | U3: Bus_new | V3: Bus_used | W3: Motorcycles (not mopeds)
A4: 1968<= | B4: 60.844617 | C4: 52.661233 | D4: 11.354349 | E4: 10.169861 | F4: 2.4978644 | G4: 0.30531472 | H4: 0.19238253 | I4: 0.090874607 | J4: 10.819607 | K4: 133.80279 | L4: 1.1385299 | M4: 51189 | N4: 373 | O4: 26399 | P4: 18426 | Q4: 4009 | R4: 2799 | S4: 1425 | T4: 226 | U4: 70 | V4: 16 | W4: 5333
A5: 1969-1974 | B5: 58.562323 | C5: 16.728968 | D5: 11.569642 | E5: 3.2189527 | F5: 2.8582124 | G5: 0.29731968 | H5: 0.41463334 | I5: 0.040054445 | J5: 5.8103235 | K5: 88.389512 | L5: 1.4765939 | M5: 32131 | N5: 482 | O5: 22453 | P5: 6176 | Q5: 3165 | R5: 852 | S5: 1336 | T5: 75 | U5: 70 | V5: 6 | W5: 3893
A6: 1975-1979 | B6: 15.003916 | C6: 6.4268518 | D6: 14.632776 | E6: 4.8171424 | F6: 1.1979817 | G6: 0.1555339 | H6: 0.8398946 | I6: 0.13303669 | J6: 4.7093167 | K6: 38.488573 | L6: 2.2877144 | M6: 21010 | N6: 831 | O6: 13183 | P6: 3499 | Q6: 4283 | R6: 921 | S6: 1925 | T6: 158 | U6: 198 | V6: 28 | W6: 3769
A7: 1980-1984 | B7: 29.883285 | C7: 13.103675 | D7: 24.958907 | E7: 6.4273405 | F7: 6.6756569 | G7: 2.1691994 | H7: 1.2099232 | I7: 0.28816341 | J7: 6.8372233 | K7: 66.201718 | L7: 8.0419641 | M7: 22167 | N7: 2657 | O7: 10998 | P7: 5867 | Q7: 6628 | R7: 1366 | S7: 3351 | T7: 1058 | U7: 223 | V7: 107 | W7: 5073
A8: 1985-1989 | B8: 49.637817 | C8: 46.248926 | D8: 30.486359 | E8: 24.862651 | F8: 14.334459 | G8: 16.027762 | H8: 1.4387653 | I8: 2.3899474 | J8: 12.701708 | K8: 116.6347 | L8: 34.572719 | M8: 38458 | N8: 10265 | O8: 16434 | P8: 17474 | Q8: 8275 | R8: 6562 | S8: 4962 | T8: 5948 | U8: 232 | V8: 438 | W8: 7721
A9: 1990-1994 | B9: 139.00015 | C9: 292.07225 | D9: 86.612825 | E9: 58.194241 | F9: 25.140845 | G9: 54.815578 | H9: 1.9007858 | I9: 5.5314976 | J9: 10.012504 | K9: 386.20704 | L9: 189.55684 | M9: 92761 | N9: 39965 | O9: 31672 | P9: 69621 | Q9: 18943 | R9: 12530 | S9: 5602 | T9: 12397 | U9: 179 | V9: 743 | W9: 5742
A10: 1995-1999 | B10: 352.73151 | C10: 1110.6051 | D10: 138.77489 | E10: 99.51634 | F10: 48.455311 | G10: 85.312816 | H10: 4.6756022 | I10: 4.9735423 | J10: 16.493396 | K10: 1225.7051 | L10: 475.6485 | M10: 209791 | N10: 71001 | O10: 62527 | P10: 177775 | Q10: 24262 | R10: 16283 | S10: 6969 | T10: 12953 | U10: 410 | V10: 530 | W10: 9267
A11: 2000-2004 | B11: 1130.8697 | C11: 2088.9855 | D11: 388.28306 | E11: 89.522759 | F11: 168.30953 | G11: 18.245172 | H11: 18.301516 | I11: 1.6282048 | J11: 28.465594 | K11: 3282.7134 | L11: 404.00878 | M11: 433322 | N11: 54426 | O11: 163113 | P11: 259823 | Q11: 55026 | R11: 10922 | S11: 13511 | T11: 2250 | U11: 848 | V11: 132 | W11: 15998
A12: 2005-2009 | B12: 2360.9019 | C12: 6759.641 | D12: 775.14973 | E12: 330.05272 | F12: 257.27333 | G12: 104.02311 | H12: 30.424964 | I12: 6.2094726 | J12: 57.697983 | K12: 8984.8421 | L12: 1090.6037 | M12: 959246 | N12: 105979 | O12: 279005 | P12: 692899 | Q12: 77629 | R12: 28503 | S12: 14968 | T12: 8618 | U12: 1117 | V12: 385 | W12: 30007
A13: 2010-2014 | B13: 3542.7148 | C13: 4194.0846 | D13: 1393.8159 | E13: 372.67862 | F13: 395.25868 | G13: 121.83617 | H13: 50.35172 | I13: 6.9628938 | J13: 50.562161 | K13: 5775.4184 | L13: 2376.2594 | M13: 580001 | N13: 183524 | O13: 350852 | P13: 391169 | Q13: 104057 | R13: 27733 | S13: 15672 | T13: 8302 | U13: 1446 | V13: 331 | W13: 22090
A14: 2015-2019 | B14: 5974.0302 | C14: 1436.5009 | D14: 3485.7433 | E14: 196.74729 | F14: 965.83358 | G14: 63.182851 | H14: 112.11638 | I14: 3.0173822 | J14: 86.935325 | K14: 5185.3752 | L14: 4753.3786 | M14: 473512 | N14: 292363 | O14: 508735 | P14: 131848 | Q14: 204384 | R14: 14713 | S14: 25794 | T14: 3587 | U14: 2783 | V14: 122 | W14: 30667
A15: 2020-2024 | B15: 5200.4922 | C15: 51.534398 | D15: 2924.1441 | E15: 20.22758 | F15: 875.43523 | G15: 7.2004714 | H15: 39.731859 | I15: 0.04562069 | J15: 57.763744 | K15: 3209.435 | L15: 3420.3477 | M15: 255793 | N15: 185286 | O15: 419360 | P15: 6361 | Q15: 151866 | R15: 2235 | S15: 25107 | T15: 424 | U15: 1286 | V15: 3 | W15: 30150
M17: (*) if a vehicle is in the fleet for part of the year then that fraction is included in the calculation above, ie a truck in the fleet all year plus another for 3 months = 1.25 fleet years
B19: Travel (million vkm) | K19: Travel per vehicle
A20: YoM | B20: Light fleet New | C20: Light fleet used import | D20: Trucks | E20: Buses | F20: Motorcycles | G20: Truck | H20: Bus | I20: Truck vehicle share | J20: Bus vehicle share | K20: Travel per new light passenger | L20: Travel per used light passenger | M20: Travel per new light commercial | N20: Travel per used light commercial | O20: Travel per light petrol vehicle | P20: Travel per light diesel vehicle | Q20: Travel per New truck | R20: Travel per used import truck | S20: Travel per New bus | T20: Travel per used import bus | U20: Travel per motorcycle
A21: 1968<= | B21: =B4+D4 -> 72.198966 | C21: =C4+E4 -> 62.831094 | D21: =F4+G4 -> 2.8031791 | E21: =H4+I4 -> 0.28325714 | F21: =J4 -> 10.819607
A22: 1969-1974 | B22: =B5+D5 -> 70.131965 | C22: =C5+E5 -> 19.94792 | D22: =F5+G5 -> 3.1555321 | E22: =H5+I5 -> 0.45468779 | F22: =J5 -> 5.8103235
A23: 1975-1979 | B23: =B6+D6 -> 29.636692 | C23: =C6+E6 -> 11.243994 | D23: =F6+G6 -> 1.3535156 | E23: =H6+I6 -> 0.9729313 | F23: =J6 -> 4.7093167
A24: 1980-1984 | B24: =B7+D7 -> 54.842193 | C24: =C7+E7 -> 19.531016 | D24: =F7+G7 -> 8.8448563 | E24: =H7+I7 -> 1.4980866 | F24: =J7 -> 6.8372233 | G24: =D24/SUM(D$24:D$32) -> 0.0027387443 | H24: =E24/SUM(E$24:E$32) -> 0.0051445593 | I24: =(S7+T7)/SUM(S$7:T$15) -> 0.025712503 | J24: =(U7+V7)/SUM(U$7:V$15) -> 0.029164825 | K24: =B7/O7*1000000 -> 2717.1563 | L24: =C7/P7*1000000 -> 2233.4541 | M24: =D7/Q7*1000000 -> 3765.677 | N24: =E7/R7*1000000 -> 4705.2273 | O24: =K7/M7*1000000 -> 2986.4988 | P24: =L7/N7*1000000 -> 3026.7083 | Q24: =F7/S7*1000000 -> 1992.1387 | R24: =G7/T7*1000000 -> 2050.283 | S24: =H7/U7*1000000 -> 5425.6645 | T24: =I7/V7*1000000 -> 2693.116 | U24: =J7/W7*1000000 -> 1347.7673
